{
  "nbformat": 4,
  "nbformat_minor": 0,
  "metadata": {
    "colab": {
      "provenance": [],
      "authorship_tag": "ABX9TyM1NTf8h8gz8jT/PbqwdG/e",
      "include_colab_link": true
    },
    "kernelspec": {
      "name": "python3",
      "display_name": "Python 3"
    },
    "language_info": {
      "name": "python"
    }
  },
  "cells": [
    {
      "cell_type": "markdown",
      "metadata": {
        "id": "view-in-github",
        "colab_type": "text"
      },
      "source": [
        "<a href=\"https://colab.research.google.com/github/klebermagno/LLM/blob/main/Image.ipynb\" target=\"_parent\"><img src=\"https://colab.research.google.com/assets/colab-badge.svg\" alt=\"Open In Colab\"/></a>"
      ]
    },
    {
      "cell_type": "code",
      "source": [
        "!pip install transformers"
      ],
      "metadata": {
        "colab": {
          "base_uri": "https://localhost:8080/"
        },
        "id": "3yYG2KXj0G-_",
        "outputId": "de1fe109-dcbe-4b1d-99c5-7b3dff4f7dbd"
      },
      "execution_count": 2,
      "outputs": [
        {
          "output_type": "stream",
          "name": "stdout",
          "text": [
            "Requirement already satisfied: transformers in /usr/local/lib/python3.10/dist-packages (4.35.2)\n",
            "Requirement already satisfied: filelock in /usr/local/lib/python3.10/dist-packages (from transformers) (3.13.1)\n",
            "Requirement already satisfied: huggingface-hub<1.0,>=0.16.4 in /usr/local/lib/python3.10/dist-packages (from transformers) (0.19.4)\n",
            "Requirement already satisfied: numpy>=1.17 in /usr/local/lib/python3.10/dist-packages (from transformers) (1.23.5)\n",
            "Requirement already satisfied: packaging>=20.0 in /usr/local/lib/python3.10/dist-packages (from transformers) (23.2)\n",
            "Requirement already satisfied: pyyaml>=5.1 in /usr/local/lib/python3.10/dist-packages (from transformers) (6.0.1)\n",
            "Requirement already satisfied: regex!=2019.12.17 in /usr/local/lib/python3.10/dist-packages (from transformers) (2023.6.3)\n",
            "Requirement already satisfied: requests in /usr/local/lib/python3.10/dist-packages (from transformers) (2.31.0)\n",
            "Requirement already satisfied: tokenizers<0.19,>=0.14 in /usr/local/lib/python3.10/dist-packages (from transformers) (0.15.0)\n",
            "Requirement already satisfied: safetensors>=0.3.1 in /usr/local/lib/python3.10/dist-packages (from transformers) (0.4.1)\n",
            "Requirement already satisfied: tqdm>=4.27 in /usr/local/lib/python3.10/dist-packages (from transformers) (4.66.1)\n",
            "Requirement already satisfied: fsspec>=2023.5.0 in /usr/local/lib/python3.10/dist-packages (from huggingface-hub<1.0,>=0.16.4->transformers) (2023.6.0)\n",
            "Requirement already satisfied: typing-extensions>=3.7.4.3 in /usr/local/lib/python3.10/dist-packages (from huggingface-hub<1.0,>=0.16.4->transformers) (4.5.0)\n",
            "Requirement already satisfied: charset-normalizer<4,>=2 in /usr/local/lib/python3.10/dist-packages (from requests->transformers) (3.3.2)\n",
            "Requirement already satisfied: idna<4,>=2.5 in /usr/local/lib/python3.10/dist-packages (from requests->transformers) (3.6)\n",
            "Requirement already satisfied: urllib3<3,>=1.21.1 in /usr/local/lib/python3.10/dist-packages (from requests->transformers) (2.0.7)\n",
            "Requirement already satisfied: certifi>=2017.4.17 in /usr/local/lib/python3.10/dist-packages (from requests->transformers) (2023.11.17)\n"
          ]
        }
      ]
    },
    {
      "cell_type": "markdown",
      "source": [],
      "metadata": {
        "id": "Nvg8BVzs0D7a"
      }
    },
    {
      "cell_type": "code",
      "source": [
        "from transformers import AutoTokenizer, AutoModelForCausalLM\n",
        "from PIL import Image\n",
        "import requests\n",
        "\n",
        "# Substitua pelo modelo de geração de imagem desejado\n",
        "model_name = \"DALL-E\"\n",
        "\n",
        "tokenizer = AutoTokenizer.from_pretrained(model_name)\n",
        "model = AutoModelForCausalLM.from_pretrained(model_name)\n",
        "\n",
        "# Substitua isso pelo seu prompt de texto\n",
        "text = \"uma descrição da imagem que você quer gerar\"\n",
        "\n",
        "inputs = tokenizer(text, return_tensors=\"pt\")\n",
        "outputs = model.generate(**inputs)\n",
        "\n",
        "# Processa a saída do modelo para uma imagem (este método pode variar)\n",
        "image = Image.open(requests.get(outputs[0], stream=True).raw)\n",
        "image.show()\n"
      ],
      "metadata": {
        "colab": {
          "base_uri": "https://localhost:8080/",
          "height": 691
        },
        "id": "FiuFfmWr0DSt",
        "outputId": "d516c80a-551f-4fd2-a85b-d66d5c49c965"
      },
      "execution_count": 5,
      "outputs": [
        {
          "output_type": "error",
          "ename": "OSError",
          "evalue": "ignored",
          "traceback": [
            "\u001b[0;31m---------------------------------------------------------------------------\u001b[0m",
            "\u001b[0;31mHTTPError\u001b[0m                                 Traceback (most recent call last)",
            "\u001b[0;32m/usr/local/lib/python3.10/dist-packages/huggingface_hub/utils/_errors.py\u001b[0m in \u001b[0;36mhf_raise_for_status\u001b[0;34m(response, endpoint_name)\u001b[0m\n\u001b[1;32m    269\u001b[0m     \u001b[0;32mtry\u001b[0m\u001b[0;34m:\u001b[0m\u001b[0;34m\u001b[0m\u001b[0;34m\u001b[0m\u001b[0m\n\u001b[0;32m--> 270\u001b[0;31m         \u001b[0mresponse\u001b[0m\u001b[0;34m.\u001b[0m\u001b[0mraise_for_status\u001b[0m\u001b[0;34m(\u001b[0m\u001b[0;34m)\u001b[0m\u001b[0;34m\u001b[0m\u001b[0;34m\u001b[0m\u001b[0m\n\u001b[0m\u001b[1;32m    271\u001b[0m     \u001b[0;32mexcept\u001b[0m \u001b[0mHTTPError\u001b[0m \u001b[0;32mas\u001b[0m \u001b[0me\u001b[0m\u001b[0;34m:\u001b[0m\u001b[0;34m\u001b[0m\u001b[0;34m\u001b[0m\u001b[0m\n",
            "\u001b[0;32m/usr/local/lib/python3.10/dist-packages/requests/models.py\u001b[0m in \u001b[0;36mraise_for_status\u001b[0;34m(self)\u001b[0m\n\u001b[1;32m   1020\u001b[0m         \u001b[0;32mif\u001b[0m \u001b[0mhttp_error_msg\u001b[0m\u001b[0;34m:\u001b[0m\u001b[0;34m\u001b[0m\u001b[0;34m\u001b[0m\u001b[0m\n\u001b[0;32m-> 1021\u001b[0;31m             \u001b[0;32mraise\u001b[0m \u001b[0mHTTPError\u001b[0m\u001b[0;34m(\u001b[0m\u001b[0mhttp_error_msg\u001b[0m\u001b[0;34m,\u001b[0m \u001b[0mresponse\u001b[0m\u001b[0;34m=\u001b[0m\u001b[0mself\u001b[0m\u001b[0;34m)\u001b[0m\u001b[0;34m\u001b[0m\u001b[0;34m\u001b[0m\u001b[0m\n\u001b[0m\u001b[1;32m   1022\u001b[0m \u001b[0;34m\u001b[0m\u001b[0m\n",
            "\u001b[0;31mHTTPError\u001b[0m: 401 Client Error: Unauthorized for url: https://huggingface.co/DALL-E/resolve/main/tokenizer_config.json",
            "\nThe above exception was the direct cause of the following exception:\n",
            "\u001b[0;31mRepositoryNotFoundError\u001b[0m                   Traceback (most recent call last)",
            "\u001b[0;32m/usr/local/lib/python3.10/dist-packages/transformers/utils/hub.py\u001b[0m in \u001b[0;36mcached_file\u001b[0;34m(path_or_repo_id, filename, cache_dir, force_download, resume_download, proxies, token, revision, local_files_only, subfolder, repo_type, user_agent, _raise_exceptions_for_missing_entries, _raise_exceptions_for_connection_errors, _commit_hash, **deprecated_kwargs)\u001b[0m\n\u001b[1;32m    429\u001b[0m         \u001b[0;31m# Load from URL or cache if already cached\u001b[0m\u001b[0;34m\u001b[0m\u001b[0;34m\u001b[0m\u001b[0m\n\u001b[0;32m--> 430\u001b[0;31m         resolved_file = hf_hub_download(\n\u001b[0m\u001b[1;32m    431\u001b[0m             \u001b[0mpath_or_repo_id\u001b[0m\u001b[0;34m,\u001b[0m\u001b[0;34m\u001b[0m\u001b[0;34m\u001b[0m\u001b[0m\n",
            "\u001b[0;32m/usr/local/lib/python3.10/dist-packages/huggingface_hub/utils/_validators.py\u001b[0m in \u001b[0;36m_inner_fn\u001b[0;34m(*args, **kwargs)\u001b[0m\n\u001b[1;32m    117\u001b[0m \u001b[0;34m\u001b[0m\u001b[0m\n\u001b[0;32m--> 118\u001b[0;31m         \u001b[0;32mreturn\u001b[0m \u001b[0mfn\u001b[0m\u001b[0;34m(\u001b[0m\u001b[0;34m*\u001b[0m\u001b[0margs\u001b[0m\u001b[0;34m,\u001b[0m \u001b[0;34m**\u001b[0m\u001b[0mkwargs\u001b[0m\u001b[0;34m)\u001b[0m\u001b[0;34m\u001b[0m\u001b[0;34m\u001b[0m\u001b[0m\n\u001b[0m\u001b[1;32m    119\u001b[0m \u001b[0;34m\u001b[0m\u001b[0m\n",
            "\u001b[0;32m/usr/local/lib/python3.10/dist-packages/huggingface_hub/file_download.py\u001b[0m in \u001b[0;36mhf_hub_download\u001b[0;34m(repo_id, filename, subfolder, repo_type, revision, library_name, library_version, cache_dir, local_dir, local_dir_use_symlinks, user_agent, force_download, force_filename, proxies, etag_timeout, resume_download, token, local_files_only, legacy_cache_layout, endpoint)\u001b[0m\n\u001b[1;32m   1373\u001b[0m             \u001b[0;31m# Repo not found => let's raise the actual error\u001b[0m\u001b[0;34m\u001b[0m\u001b[0;34m\u001b[0m\u001b[0m\n\u001b[0;32m-> 1374\u001b[0;31m             \u001b[0;32mraise\u001b[0m \u001b[0mhead_call_error\u001b[0m\u001b[0;34m\u001b[0m\u001b[0;34m\u001b[0m\u001b[0m\n\u001b[0m\u001b[1;32m   1375\u001b[0m         \u001b[0;32melse\u001b[0m\u001b[0;34m:\u001b[0m\u001b[0;34m\u001b[0m\u001b[0;34m\u001b[0m\u001b[0m\n",
            "\u001b[0;32m/usr/local/lib/python3.10/dist-packages/huggingface_hub/file_download.py\u001b[0m in \u001b[0;36mhf_hub_download\u001b[0;34m(repo_id, filename, subfolder, repo_type, revision, library_name, library_version, cache_dir, local_dir, local_dir_use_symlinks, user_agent, force_download, force_filename, proxies, etag_timeout, resume_download, token, local_files_only, legacy_cache_layout, endpoint)\u001b[0m\n\u001b[1;32m   1246\u001b[0m             \u001b[0;32mtry\u001b[0m\u001b[0;34m:\u001b[0m\u001b[0;34m\u001b[0m\u001b[0;34m\u001b[0m\u001b[0m\n\u001b[0;32m-> 1247\u001b[0;31m                 metadata = get_hf_file_metadata(\n\u001b[0m\u001b[1;32m   1248\u001b[0m                     \u001b[0murl\u001b[0m\u001b[0;34m=\u001b[0m\u001b[0murl\u001b[0m\u001b[0;34m,\u001b[0m\u001b[0;34m\u001b[0m\u001b[0;34m\u001b[0m\u001b[0m\n",
            "\u001b[0;32m/usr/local/lib/python3.10/dist-packages/huggingface_hub/utils/_validators.py\u001b[0m in \u001b[0;36m_inner_fn\u001b[0;34m(*args, **kwargs)\u001b[0m\n\u001b[1;32m    117\u001b[0m \u001b[0;34m\u001b[0m\u001b[0m\n\u001b[0;32m--> 118\u001b[0;31m         \u001b[0;32mreturn\u001b[0m \u001b[0mfn\u001b[0m\u001b[0;34m(\u001b[0m\u001b[0;34m*\u001b[0m\u001b[0margs\u001b[0m\u001b[0;34m,\u001b[0m \u001b[0;34m**\u001b[0m\u001b[0mkwargs\u001b[0m\u001b[0;34m)\u001b[0m\u001b[0;34m\u001b[0m\u001b[0;34m\u001b[0m\u001b[0m\n\u001b[0m\u001b[1;32m    119\u001b[0m \u001b[0;34m\u001b[0m\u001b[0m\n",
            "\u001b[0;32m/usr/local/lib/python3.10/dist-packages/huggingface_hub/file_download.py\u001b[0m in \u001b[0;36mget_hf_file_metadata\u001b[0;34m(url, token, proxies, timeout)\u001b[0m\n\u001b[1;32m   1623\u001b[0m     \u001b[0;31m# Retrieve metadata\u001b[0m\u001b[0;34m\u001b[0m\u001b[0;34m\u001b[0m\u001b[0m\n\u001b[0;32m-> 1624\u001b[0;31m     r = _request_wrapper(\n\u001b[0m\u001b[1;32m   1625\u001b[0m         \u001b[0mmethod\u001b[0m\u001b[0;34m=\u001b[0m\u001b[0;34m\"HEAD\"\u001b[0m\u001b[0;34m,\u001b[0m\u001b[0;34m\u001b[0m\u001b[0;34m\u001b[0m\u001b[0m\n",
            "\u001b[0;32m/usr/local/lib/python3.10/dist-packages/huggingface_hub/file_download.py\u001b[0m in \u001b[0;36m_request_wrapper\u001b[0;34m(method, url, follow_relative_redirects, **params)\u001b[0m\n\u001b[1;32m    401\u001b[0m     \u001b[0;32mif\u001b[0m \u001b[0mfollow_relative_redirects\u001b[0m\u001b[0;34m:\u001b[0m\u001b[0;34m\u001b[0m\u001b[0;34m\u001b[0m\u001b[0m\n\u001b[0;32m--> 402\u001b[0;31m         response = _request_wrapper(\n\u001b[0m\u001b[1;32m    403\u001b[0m             \u001b[0mmethod\u001b[0m\u001b[0;34m=\u001b[0m\u001b[0mmethod\u001b[0m\u001b[0;34m,\u001b[0m\u001b[0;34m\u001b[0m\u001b[0;34m\u001b[0m\u001b[0m\n",
            "\u001b[0;32m/usr/local/lib/python3.10/dist-packages/huggingface_hub/file_download.py\u001b[0m in \u001b[0;36m_request_wrapper\u001b[0;34m(method, url, follow_relative_redirects, **params)\u001b[0m\n\u001b[1;32m    425\u001b[0m     \u001b[0mresponse\u001b[0m \u001b[0;34m=\u001b[0m \u001b[0mget_session\u001b[0m\u001b[0;34m(\u001b[0m\u001b[0;34m)\u001b[0m\u001b[0;34m.\u001b[0m\u001b[0mrequest\u001b[0m\u001b[0;34m(\u001b[0m\u001b[0mmethod\u001b[0m\u001b[0;34m=\u001b[0m\u001b[0mmethod\u001b[0m\u001b[0;34m,\u001b[0m \u001b[0murl\u001b[0m\u001b[0;34m=\u001b[0m\u001b[0murl\u001b[0m\u001b[0;34m,\u001b[0m \u001b[0;34m**\u001b[0m\u001b[0mparams\u001b[0m\u001b[0;34m)\u001b[0m\u001b[0;34m\u001b[0m\u001b[0;34m\u001b[0m\u001b[0m\n\u001b[0;32m--> 426\u001b[0;31m     \u001b[0mhf_raise_for_status\u001b[0m\u001b[0;34m(\u001b[0m\u001b[0mresponse\u001b[0m\u001b[0;34m)\u001b[0m\u001b[0;34m\u001b[0m\u001b[0;34m\u001b[0m\u001b[0m\n\u001b[0m\u001b[1;32m    427\u001b[0m     \u001b[0;32mreturn\u001b[0m \u001b[0mresponse\u001b[0m\u001b[0;34m\u001b[0m\u001b[0;34m\u001b[0m\u001b[0m\n",
            "\u001b[0;32m/usr/local/lib/python3.10/dist-packages/huggingface_hub/utils/_errors.py\u001b[0m in \u001b[0;36mhf_raise_for_status\u001b[0;34m(response, endpoint_name)\u001b[0m\n\u001b[1;32m    319\u001b[0m             )\n\u001b[0;32m--> 320\u001b[0;31m             \u001b[0;32mraise\u001b[0m \u001b[0mRepositoryNotFoundError\u001b[0m\u001b[0;34m(\u001b[0m\u001b[0mmessage\u001b[0m\u001b[0;34m,\u001b[0m \u001b[0mresponse\u001b[0m\u001b[0;34m)\u001b[0m \u001b[0;32mfrom\u001b[0m \u001b[0me\u001b[0m\u001b[0;34m\u001b[0m\u001b[0;34m\u001b[0m\u001b[0m\n\u001b[0m\u001b[1;32m    321\u001b[0m \u001b[0;34m\u001b[0m\u001b[0m\n",
            "\u001b[0;31mRepositoryNotFoundError\u001b[0m: 401 Client Error. (Request ID: Root=1-65871f4e-0bc898d36498ae2102879b20;c27d7bd4-ed82-46c4-9de0-eccf7548f435)\n\nRepository Not Found for url: https://huggingface.co/DALL-E/resolve/main/tokenizer_config.json.\nPlease make sure you specified the correct `repo_id` and `repo_type`.\nIf you are trying to access a private or gated repo, make sure you are authenticated.\nInvalid username or password.",
            "\nThe above exception was the direct cause of the following exception:\n",
            "\u001b[0;31mOSError\u001b[0m                                   Traceback (most recent call last)",
            "\u001b[0;32m<ipython-input-5-edf442823e3c>\u001b[0m in \u001b[0;36m<cell line: 8>\u001b[0;34m()\u001b[0m\n\u001b[1;32m      6\u001b[0m \u001b[0mmodel_name\u001b[0m \u001b[0;34m=\u001b[0m \u001b[0;34m\"DALL-E\"\u001b[0m\u001b[0;34m\u001b[0m\u001b[0;34m\u001b[0m\u001b[0m\n\u001b[1;32m      7\u001b[0m \u001b[0;34m\u001b[0m\u001b[0m\n\u001b[0;32m----> 8\u001b[0;31m \u001b[0mtokenizer\u001b[0m \u001b[0;34m=\u001b[0m \u001b[0mAutoTokenizer\u001b[0m\u001b[0;34m.\u001b[0m\u001b[0mfrom_pretrained\u001b[0m\u001b[0;34m(\u001b[0m\u001b[0mmodel_name\u001b[0m\u001b[0;34m)\u001b[0m\u001b[0;34m\u001b[0m\u001b[0;34m\u001b[0m\u001b[0m\n\u001b[0m\u001b[1;32m      9\u001b[0m \u001b[0mmodel\u001b[0m \u001b[0;34m=\u001b[0m \u001b[0mAutoModelForCausalLM\u001b[0m\u001b[0;34m.\u001b[0m\u001b[0mfrom_pretrained\u001b[0m\u001b[0;34m(\u001b[0m\u001b[0mmodel_name\u001b[0m\u001b[0;34m)\u001b[0m\u001b[0;34m\u001b[0m\u001b[0;34m\u001b[0m\u001b[0m\n\u001b[1;32m     10\u001b[0m \u001b[0;34m\u001b[0m\u001b[0m\n",
            "\u001b[0;32m/usr/local/lib/python3.10/dist-packages/transformers/models/auto/tokenization_auto.py\u001b[0m in \u001b[0;36mfrom_pretrained\u001b[0;34m(cls, pretrained_model_name_or_path, *inputs, **kwargs)\u001b[0m\n\u001b[1;32m    716\u001b[0m \u001b[0;34m\u001b[0m\u001b[0m\n\u001b[1;32m    717\u001b[0m         \u001b[0;31m# Next, let's try to use the tokenizer_config file to get the tokenizer class.\u001b[0m\u001b[0;34m\u001b[0m\u001b[0;34m\u001b[0m\u001b[0m\n\u001b[0;32m--> 718\u001b[0;31m         \u001b[0mtokenizer_config\u001b[0m \u001b[0;34m=\u001b[0m \u001b[0mget_tokenizer_config\u001b[0m\u001b[0;34m(\u001b[0m\u001b[0mpretrained_model_name_or_path\u001b[0m\u001b[0;34m,\u001b[0m \u001b[0;34m**\u001b[0m\u001b[0mkwargs\u001b[0m\u001b[0;34m)\u001b[0m\u001b[0;34m\u001b[0m\u001b[0;34m\u001b[0m\u001b[0m\n\u001b[0m\u001b[1;32m    719\u001b[0m         \u001b[0;32mif\u001b[0m \u001b[0;34m\"_commit_hash\"\u001b[0m \u001b[0;32min\u001b[0m \u001b[0mtokenizer_config\u001b[0m\u001b[0;34m:\u001b[0m\u001b[0;34m\u001b[0m\u001b[0;34m\u001b[0m\u001b[0m\n\u001b[1;32m    720\u001b[0m             \u001b[0mkwargs\u001b[0m\u001b[0;34m[\u001b[0m\u001b[0;34m\"_commit_hash\"\u001b[0m\u001b[0;34m]\u001b[0m \u001b[0;34m=\u001b[0m \u001b[0mtokenizer_config\u001b[0m\u001b[0;34m[\u001b[0m\u001b[0;34m\"_commit_hash\"\u001b[0m\u001b[0;34m]\u001b[0m\u001b[0;34m\u001b[0m\u001b[0;34m\u001b[0m\u001b[0m\n",
            "\u001b[0;32m/usr/local/lib/python3.10/dist-packages/transformers/models/auto/tokenization_auto.py\u001b[0m in \u001b[0;36mget_tokenizer_config\u001b[0;34m(pretrained_model_name_or_path, cache_dir, force_download, resume_download, proxies, token, revision, local_files_only, subfolder, **kwargs)\u001b[0m\n\u001b[1;32m    548\u001b[0m \u001b[0;34m\u001b[0m\u001b[0m\n\u001b[1;32m    549\u001b[0m     \u001b[0mcommit_hash\u001b[0m \u001b[0;34m=\u001b[0m \u001b[0mkwargs\u001b[0m\u001b[0;34m.\u001b[0m\u001b[0mget\u001b[0m\u001b[0;34m(\u001b[0m\u001b[0;34m\"_commit_hash\"\u001b[0m\u001b[0;34m,\u001b[0m \u001b[0;32mNone\u001b[0m\u001b[0;34m)\u001b[0m\u001b[0;34m\u001b[0m\u001b[0;34m\u001b[0m\u001b[0m\n\u001b[0;32m--> 550\u001b[0;31m     resolved_config_file = cached_file(\n\u001b[0m\u001b[1;32m    551\u001b[0m         \u001b[0mpretrained_model_name_or_path\u001b[0m\u001b[0;34m,\u001b[0m\u001b[0;34m\u001b[0m\u001b[0;34m\u001b[0m\u001b[0m\n\u001b[1;32m    552\u001b[0m         \u001b[0mTOKENIZER_CONFIG_FILE\u001b[0m\u001b[0;34m,\u001b[0m\u001b[0;34m\u001b[0m\u001b[0;34m\u001b[0m\u001b[0m\n",
            "\u001b[0;32m/usr/local/lib/python3.10/dist-packages/transformers/utils/hub.py\u001b[0m in \u001b[0;36mcached_file\u001b[0;34m(path_or_repo_id, filename, cache_dir, force_download, resume_download, proxies, token, revision, local_files_only, subfolder, repo_type, user_agent, _raise_exceptions_for_missing_entries, _raise_exceptions_for_connection_errors, _commit_hash, **deprecated_kwargs)\u001b[0m\n\u001b[1;32m    449\u001b[0m         ) from e\n\u001b[1;32m    450\u001b[0m     \u001b[0;32mexcept\u001b[0m \u001b[0mRepositoryNotFoundError\u001b[0m \u001b[0;32mas\u001b[0m \u001b[0me\u001b[0m\u001b[0;34m:\u001b[0m\u001b[0;34m\u001b[0m\u001b[0;34m\u001b[0m\u001b[0m\n\u001b[0;32m--> 451\u001b[0;31m         raise EnvironmentError(\n\u001b[0m\u001b[1;32m    452\u001b[0m             \u001b[0;34mf\"{path_or_repo_id} is not a local folder and is not a valid model identifier \"\u001b[0m\u001b[0;34m\u001b[0m\u001b[0;34m\u001b[0m\u001b[0m\n\u001b[1;32m    453\u001b[0m             \u001b[0;34m\"listed on 'https://huggingface.co/models'\\nIf this is a private repository, make sure to pass a token \"\u001b[0m\u001b[0;34m\u001b[0m\u001b[0;34m\u001b[0m\u001b[0m\n",
            "\u001b[0;31mOSError\u001b[0m: DALL-E is not a local folder and is not a valid model identifier listed on 'https://huggingface.co/models'\nIf this is a private repository, make sure to pass a token having permission to this repo either by logging in with `huggingface-cli login` or by passing `token=<your_token>`"
          ]
        }
      ]
    },
    {
      "cell_type": "code",
      "execution_count": null,
      "metadata": {
        "id": "QjwtOjvXz_pK"
      },
      "outputs": [],
      "source": []
    },
    {
      "cell_type": "markdown",
      "source": [],
      "metadata": {
        "id": "YoQ3FA200B31"
      }
    }
  ]
}